<?xml version="1.0" encoding="utf-8"?>
<!-- This URDF was automatically created by SolidWorks to URDF Exporter! Originally created by Stephen Brawner (brawner@gmail.com) 
     Commit Version: 1.6.0-4-g7f85cfe  Build Version: 1.6.7995.38578
     For more information, please see http://wiki.ros.org/sw_urdf_exporter -->
<robot
  name="bassie.SLDASM">
  <link
    name="pelvis">
    <inertial>
      <origin
        xyz="-1.0894E-18 -0.005 -0.0014137"
        rpy="0 0 0" />
      <mass
        value="0.030372" />
      <inertia
        ixx="3.7439E-06"
        ixy="5.1118E-23"
        ixz="8.5129E-22"
        iyy="2.4933E-05"
        iyz="-1.5293E-22"
        izz="2.1695E-05" />
    </inertial>
    <visual>
      <origin
        xyz="0 0 0"
        rpy="0 0 0" />
      <geometry>
        <mesh
          filename="meshes/pelvis.STL" />
      </geometry>
      <material
        name="">
        <color
          rgba="1 1 1 1" />
      </material>
    </visual>
    <collision>
      <origin
        xyz="0 0 0"
        rpy="0 0 0" />
      <geometry>
        <mesh
          filename="meshes/pelvis.STL" />
      </geometry>
    </collision>
  </link>
  <link
    name="right_hip_roll">
    <inertial>
      <origin
        xyz="0 -0.0110100876761759 -0.0109899123238241"
        rpy="0 0 0" />
      <mass
        value="0.0104219467105846" />
      <inertia
        ixx="1.70463571115033E-06"
        ixy="-3.84638984837158E-23"
        ixz="-2.40295967946655E-22"
        iyy="1.38650049834199E-06"
        iyz="-3.73929543448507E-07"
        izz="1.386500498342E-06" />
    </inertial>
    <visual>
      <origin
        xyz="0 0 0"
        rpy="0 0 0" />
      <geometry>
        <mesh
          filename="meshes/right_hip_roll.STL" />
      </geometry>
      <material
        name="">
        <color
          rgba="1 1 1 1" />
      </material>
    </visual>
    <collision>
      <origin
        xyz="0 0 0"
        rpy="0 0 0" />
      <geometry>
        <mesh
          filename="meshes/right_hip_roll.STL" />
      </geometry>
    </collision>
  </link>
  <joint
    name="right_hip_roll"
    type="revolute">
    <origin
      xyz="-0.039827 0 -0.0093071"
      rpy="1.5708 -0.0050327 0" />
    <parent
      link="pelvis" />
    <child
      link="right_hip_roll" />
    <axis
      xyz="0 0 1" />
    <limit
      lower="-1"
      upper="1"
      effort="100"
      velocity="100" />
  </joint>
  <link
    name="right_hip_pitch">
    <inertial>
      <origin
        xyz="6.9389E-18 -0.01101 -0.010989"
        rpy="0 0 0" />
      <mass
        value="0.010422" />
      <inertia
        ixx="1.7046E-06"
        ixy="-1.5882E-22"
        ixz="-1.052E-22"
        iyy="1.3865E-06"
        iyz="-3.7393E-07"
        izz="1.3865E-06" />
    </inertial>
    <visual>
      <origin
        xyz="0 0 0"
        rpy="0 0 0" />
      <geometry>
        <mesh
          filename="meshes/right_hip_pitch.STL" />
      </geometry>
      <material
        name="">
        <color
          rgba="1 1 1 1" />
      </material>
    </visual>
    <collision>
      <origin
        xyz="0 0 0"
        rpy="0 0 0" />
      <geometry>
        <mesh
          filename="meshes/right_hip_pitch.STL" />
      </geometry>
    </collision>
  </link>
  <joint
    name="right_hip_pitch"
    type="revolute">
    <origin
      xyz="0 -0.022001 -0.022"
      rpy="-1.5708 -1.4933 0" />
    <parent
      link="right_hip_roll" />
    <child
      link="right_hip_pitch" />
    <axis
      xyz="0 0 1" />
    <limit
      lower="-1"
      upper="1"
      effort="100"
      velocity="100" />
  </joint>
  <link
    name="right_hip_yaw">
    <inertial>
      <origin
        xyz="-0.0059259 -0.05258 0.061704"
        rpy="0 0 0" />
      <mass
        value="0.10702" />
      <inertia
        ixx="0.0005918"
        ixy="1.5987E-08"
        ixz="-1.2708E-08"
        iyy="0.00030815"
        iyz="0.00025849"
        izz="0.00028495" />
    </inertial>
    <visual>
      <origin
        xyz="0 0 0"
        rpy="0 0 0" />
      <geometry>
        <mesh
          filename="meshes/right_hip_yaw.STL" />
      </geometry>
      <material
        name="">
        <color
          rgba="1 1 1 1" />
      </material>
    </visual>
    <collision>
      <origin
        xyz="0 0 0"
        rpy="0 0 0" />
      <geometry>
        <mesh
          filename="meshes/right_hip_yaw.STL" />
      </geometry>
    </collision>
  </link>
  <joint
    name="right_hip_yaw"
    type="revolute">
    <origin
      xyz="0 -0.021068 -0.021999"
      rpy="1.4762 0 1.5708" />
    <parent
      link="right_hip_pitch" />
    <child
      link="right_hip_yaw" />0
    <axis
      xyz="1 0 0" />
    <limit
      lower="-2"
      upper="2"
      effort="100"
      velocity="100" />
  </joint>
  <link
    name="right_knee">
    <inertial>
      <origin
        xyz="-0.005932 -0.084603 0.0016889"
        rpy="0 0 0" />
      <mass
        value="0.074448" />
      <inertia
        ixx="0.00016466"
        ixy="-4.6137E-12"
        ixz="1.4921E-11"
        iyy="1.7702E-05"
        iyz="-3.9669E-06"
        izz="0.0001482" />
    </inertial>
    <visual>
      <origin
        xyz="0 0 0"
        rpy="0 0 0" />
      <geometry>
        <mesh
          filename="meshes/right_knee.STL" />
      </geometry>
      <material
        name="">
        <color
          rgba="1 1 1 1" />
      </material>
    </visual>
    <collision>
      <origin
        xyz="0 0 0"
        rpy="0 0 0" />
      <geometry>
        <mesh
          filename="meshes/right_knee.STL" />
      </geometry>
    </collision>
  </link>
  <joint
    name="right_knee"
    type="revolute">
    <origin
      xyz="0 -0.14142 0.14142"
      rpy="0.17749 0 0" />
    <parent
      link="right_hip_yaw" />
    <child
      link="right_knee" />
    <axis
      xyz="1 0 0" />
    <limit
      lower="-2"
      upper="2"
      effort="100"
      velocity="100" />
  </joint>
  <link
    name="right_ankle">
    <inertial>
      <origin
        xyz="-0.005932 -0.011738 0.0093459"
        rpy="0 0 0" />
      <mass
        value="0.014116" />
      <inertia
        ixx="9.2428E-06"
        ixy="-1.1911E-22"
        ixz="-7.1071E-21"
        iyy="8.9523E-06"
        iyz="1.0124E-07"
        izz="5.2573E-07" />
    </inertial>
    <visual>
      <origin
        xyz="0 0 0"
        rpy="0 0 0" />
      <geometry>
        <mesh
          filename="meshes/right_ankle.STL" />
      </geometry>
      <material
        name="">
        <color
          rgba="1 1 1 1" />
      </material>
    </visual>
    <collision>
      <origin
        xyz="0 0 0"
        rpy="0 0 0" />
      <geometry>
        <mesh
          filename="meshes/right_ankle.STL" />
      </geometry>
    </collision>
  </link>
  <joint
    name="right_ankle"
    type="revolute">
    <origin
      xyz="0 -0.18 0"
      rpy="-0.17083 0 0" />
    <parent
      link="right_knee" />
    <child
      link="right_ankle" />
    <axis
      xyz="1 0 0" />
    <limit
      lower="-2"
      upper="2"
      effort="100"
      velocity="100" />
  </joint>
  <link
    name="left_hip_roll">
    <inertial>
      <origin
        xyz="0.0019531 -0.010835 -0.01099"
        rpy="0 0 0" />
      <mass
        value="0.010422" />
      <inertia
        ixx="1.6946E-06"
        ixy="5.5539E-08"
        ixz="6.6331E-08"
        iyy="1.3965E-06"
        iyz="-3.68E-07"
        izz="1.3865E-06" />
    </inertial>
    <visual>
      <origin
        xyz="0 0 0"
        rpy="0 0 0" />
      <geometry>
        <mesh
          filename="meshes/left_hip_roll.STL" />
      </geometry>
      <material
        name="">
        <color
          rgba="1 1 1 1" />
      </material>
    </visual>
    <collision>
      <origin
        xyz="0 0 0"
        rpy="0 0 0" />
      <geometry>
        <mesh
          filename="meshes/left_hip_roll.STL" />
      </geometry>
    </collision>
  </link>
  <joint
    name="left_hip_roll"
    type="revolute">
    <origin
      xyz="0.039827 0 -0.0093071"
      rpy="1.5708 0.21473 0" />
    <parent
      link="pelvis" />
    <child
      link="left_hip_roll" />
    <axis
      xyz="0 0 1" />
    <limit
      lower="-1"
      upper="1"
      effort="100"
      velocity="100" />
  </joint>
  <link
    name="left_hip_pitch">
    <inertial>
      <origin
        xyz="-0.00011924416782334 -0.0166849153375323 -0.0156729058227143"
        rpy="0 0 0" />
      <mass
        value="0.0104219467105846" />
      <inertia
        ixx="1.70455481644992E-06"
        ixy="-6.14799554501199E-09"
        ixz="-5.34124844156622E-09"
        iyy="1.25609121903428E-06"
        iyz="-3.5037918893552E-07"
        izz="1.51699067235013E-06" />
    </inertial>
    <visual>
      <origin
        xyz="0 0 0"
        rpy="0 0 0" />
      <geometry>
        <mesh
          filename="meshes/left_hip_pitch.STL" />
      </geometry>
      <material
        name="">
        <color
          rgba="1 1 1 1" />
      </material>
    </visual>
    <collision>
      <origin
        xyz="0 0 0"
        rpy="0 0 0" />
      <geometry>
        <mesh
          filename="meshes/left_hip_pitch.STL" />
      </geometry>
    </collision>
  </link>
  <joint
    name="left_hip_pitch"
    type="revolute">
    <origin
      xyz="0 -0.014842 -0.022"
      rpy="-1.5708 1.5547 0" />
    <parent
      link="left_hip_roll" />
    <child
      link="left_hip_pitch" />
    <axis
      xyz="0 0 1" />
    <limit
      lower="-1"
      upper="1"
      effort="100"
      velocity="100" />
  </joint>
  <link
    name="left_hip_yaw">
    <inertial>
      <origin
        xyz="0.048673511103284 -0.0739656579197749 -0.00731838859434158"
        rpy="0 0 0" />
      <mass
        value="0.107042315965997" />
      <inertia
        ixx="0.000574314695218096"
        ixy="9.54278613038549E-05"
        ixz="1.65090849010936E-05"
        iyy="6.87578213038094E-05"
        iyz="-8.09892660763148E-05"
        izz="0.000541846725280536" />
    </inertial>
    <visual>
      <origin
        xyz="0 0 0"
        rpy="0 0 0" />
      <geometry>
        <mesh
          filename="meshes/left_hip_yaw.STL" />
      </geometry>
      <material
        name="">
        <color
          rgba="1 1 1 1" />
      </material>
    </visual>
    <collision>
      <origin
        xyz="0 0 0"
        rpy="0 0 0" />
      <geometry>
        <mesh
          filename="meshes/left_hip_yaw.STL" />
      </geometry>
    </collision>
  </link>
  <joint
    name="left_hip_yaw"
    type="revolute">
    <origin
      xyz="0 0 -0.029158"
      rpy="1.4219 0 -1.5708" />
    <parent
      link="left_hip_pitch" />
    <child
      link="left_hip_yaw" />
    <axis
      xyz="1 0 0" />
    <limit
      lower="-2"
      upper="2"
      effort="100"
      velocity="100" />
  </joint>
  <link
    name="left_knee">
    <inertial>
      <origin
        xyz="0.0634278158805573 -0.157483063920496 -0.161225323470923"
        rpy="0 0 0" />
      <mass
        value="0.0744483650191621" />
      <inertia
        ixx="0.000160028757295627"
        ixy="2.56419476464298E-05"
        ixz="-1.96246587058239E-07"
        iyy="2.22541214478718E-05"
        iyz="2.67441013425283E-06"
        izz="0.000148260278969676" />
    </inertial>
    <visual>
      <origin
        xyz="0 0 0"
        rpy="0 0 0" />
      <geometry>
        <mesh
          filename="meshes/left_knee.STL" />
      </geometry>
      <material
        name="">
        <color
          rgba="1 1 1 1" />
      </material>
    </visual>
    <collision>
      <origin
        xyz="0 0 0"
        rpy="0 0 0" />
      <geometry>
        <mesh
          filename="meshes/left_knee.STL" />
      </geometry>
    </collision>
  </link>
  <joint
    name="left_knee"
    type="revolute">
    <origin
      xyz="0.021411 -0.14142 0.14142"
      rpy="0.16142 0 0" />
    <parent
      link="left_hip_yaw" />
    <child
      link="left_knee" />
    <axis
      xyz="1 0 0" />
    <limit
      lower="-2"
      upper="2"
      effort="100"
      velocity="100" />
  </joint>
  <link
    name="left_ankle">
    <inertial>
      <origin
        xyz="0.0819824299887631 -0.0680715298382376 -0.154093152648304"
        rpy="0 0 0" />
      <mass
        value="0.0141163998019808" />
      <inertia
        ixx="9.22211598450274E-06"
        ixy="5.56287070206116E-08"
        ixz="3.20279364054552E-07"
        iyy="8.95955428550254E-06"
        iyz="-1.54088588333767E-07"
        izz="5.39201280926635E-07" />
    </inertial>
    <visual>
      <origin
        xyz="0 0 0"
        rpy="0 0 0" />
      <geometry>
        <mesh
          filename="meshes/left_ankle.STL" />
      </geometry>
      <material
        name="">
        <color
          rgba="1 1 1 1" />
      </material>
    </visual>
    <collision>
      <origin
        xyz="0 0 0"
        rpy="0 0 0" />
      <geometry>
        <mesh
          filename="meshes/left_ankle.STL" />
      </geometry>
    </collision>
  </link>
  <joint
    name="left_ankle"
    type="revolute">
    <origin
      xyz="0 -0.18 0"
      rpy="-0.090229 0 0" />
    <parent
      link="left_knee" />
    <child
      link="left_ankle" />
    <axis
      xyz="1 0 0" />
    <limit
      lower="-2"
      upper="2"
      effort="100"
      velocity="100" />
  </joint>
</robot>